#usda 1.0
(
    customLayerData = {
        string creator = "URDF USD Converter v0.1.0"
    }
    defaultPrim = "hylion"
    doc = """Generated from Composed Stage of root layer /tmp/tmp5udvdz66/hylion.usdc


Generated from Composed Stage of root layer /home/laba/project_singularity/δ3/usd/hylion_v6/usdex/hylion.usdc


Generated from Composed Stage of root layer /home/laba/project_singularity/δ3/usd/hylion_v6/temp/hylion_v6.usd


Generated from Composed Stage of root layer /home/laba/project_singularity/δ3/usd/hylion_v6/hylion_v6/payloads/base.usd
"""
    kilogramsPerUnit = 1
    metersPerUnit = 1
    upAxis = "Z"
)

over "hylion"
{
    over "Geometry"
    {
        over "base" (
            prepend apiSchemas = ["PhysicsRigidBodyAPI", "PhysicsArticulationRootAPI", "NewtonArticulationRootAPI", "PhysicsMassAPI"]
        )
        {
            bool newton:selfCollisionEnabled = 0
            point3f physics:centerOfMass = (-0.0030965, 0.000264765, 0.675059)
            float3 physics:diagonalInertia = (0.031816382, 0.044768665, 0.06676636)
            float physics:mass = 4.44401
            quatf physics:principalAxes = (0.72030956, -0.0007743648, 0.69365185, 0.0007999291)

            over "imu_2" (
                prepend apiSchemas = ["PhysicsRigidBodyAPI", "PhysicsMassAPI"]
            )
            {
                point3f physics:centerOfMass = (3.00866e-18, 9.72026e-19, 0.0025)
                float3 physics:diagonalInertia = (4.06118e-8, 1.11441e-7, 1.43815e-7)
                float physics:mass = 0.00197704
                quatf physics:principalAxes = (6.123234e-17, 0.70710677, 0.70710677, 0)

                over "imu" (
                    prepend apiSchemas = ["PhysicsRigidBodyAPI", "PhysicsMassAPI"]
                )
                {
                    point3f physics:centerOfMass = (0, 0, 0)
                    float3 physics:diagonalInertia = (0, 0, 0)
                    float physics:mass = 1e-9
                    quatf physics:principalAxes = (1, 0, 0, 0)
                }
            }

            over "leg_left_hip_roll" (
                prepend apiSchemas = ["PhysicsRigidBodyAPI", "PhysicsMassAPI"]
            )
            {
                point3f physics:centerOfMass = (-0.00410941, -0.000112596, -0.0464623)
                float3 physics:diagonalInertia = (0.0007264788, 0.00089565007, 0.0009815102)
                float physics:mass = 0.83786
                quatf physics:principalAxes = (0.7289585, -0.018860765, 0.6832451, -0.037946362)

                over "leg_left_hip_yaw" (
                    prepend apiSchemas = ["PhysicsRigidBodyAPI", "PhysicsMassAPI"]
                )
                {
                    point3f physics:centerOfMass = (-0.00411632, -0.0000863203, 0.0463382)
                    float3 physics:diagonalInertia = (0.0007225901, 0.000898328, 0.0009805659)
                    float physics:mass = 0.837683
                    quatf physics:principalAxes = (0.67939144, 0.018666932, 0.7335266, -0.0041939355)

                    over "leg_left_hip_pitch" (
                        prepend apiSchemas = ["PhysicsRigidBodyAPI", "PhysicsMassAPI"]
                    )
                    {
                        point3f physics:centerOfMass = (0.0030405, 0.120388, 0.0210924)
                        float3 physics:diagonalInertia = (0.00097285054, 0.002643212, 0.0028726575)
                        float physics:mass = 0.947974
                        quatf physics:principalAxes = (-0.5196373, 0.44408518, 0.5578758, 0.47068042)

                        over "leg_left_knee_pitch" (
                            prepend apiSchemas = ["PhysicsRigidBodyAPI", "PhysicsMassAPI"]
                        )
                        {
                            point3f physics:centerOfMass = (-0.0000414041, -0.112249, 0.0257397)
                            float3 physics:diagonalInertia = (0.0005587819, 0.002038234, 0.002301267)
                            float physics:mass = 0.653864
                            quatf physics:principalAxes = (0.5077003, -0.49231324, -0.50502497, -0.4947907)

                            over "leg_left_ankle_pitch" (
                                prepend apiSchemas = ["PhysicsRigidBodyAPI", "PhysicsMassAPI"]
                            )
                            {
                                point3f physics:centerOfMass = (0.0131065, 0.0273743, 0.0274153)
                                float3 physics:diagonalInertia = (0.00007969334, 0.0001337359, 0.00019949397)
                                float physics:mass = 0.106196
                                quatf physics:principalAxes = (0.7131654, 0.20693325, 0.6649288, 0.08027097)

                                over "leg_left_ankle_roll" (
                                    prepend apiSchemas = ["PhysicsRigidBodyAPI", "PhysicsMassAPI"]
                                )
                                {
                                    point3f physics:centerOfMass = (0.0000229341, 0.0226611, 0.0197836)
                                    float3 physics:diagonalInertia = (0.0006039032, 0.0019191763, 0.0019870535)
                                    float physics:mass = 0.706476
                                    quatf physics:principalAxes = (0.70614105, -0.041082144, 0.70593745, 0.036460835)

                                    over "box" (
                                        prepend apiSchemas = ["NewtonCollisionAPI"]
                                    )
                                    {
                                    }
                                }
                            }

                            over "cylinder" (
                                prepend apiSchemas = ["NewtonCollisionAPI"]
                            )
                            {
                            }
                        }

                        over "cylinder" (
                            prepend apiSchemas = ["NewtonCollisionAPI"]
                        )
                        {
                        }
                    }
                }
            }

            over "leg_right_hip_roll" (
                prepend apiSchemas = ["PhysicsRigidBodyAPI", "PhysicsMassAPI"]
            )
            {
                point3f physics:centerOfMass = (0.00410941, -0.00018505, -0.0464478)
                float3 physics:diagonalInertia = (0.0007261349, 0.0008962662, 0.0009809339)
                float physics:mass = 0.83786
                quatf physics:principalAxes = (0.6844831, 0.025762405, 0.7285287, 0.008068601)

                over "leg_right_hip_yaw" (
                    prepend apiSchemas = ["PhysicsRigidBodyAPI", "PhysicsMassAPI"]
                )
                {
                    point3f physics:centerOfMass = (0.00411632, -0.000013851, 0.0463238)
                    float3 physics:diagonalInertia = (0.0007222858, 0.000898597, 0.0009803402)
                    float physics:mass = 0.837683
                    quatf physics:principalAxes = (0.73274136, 0.015878888, 0.68029606, -0.0059355884)

                    over "leg_right_hip_pitch" (
                        prepend apiSchemas = ["PhysicsRigidBodyAPI", "PhysicsMassAPI"]
                    )
                    {
                        point3f physics:centerOfMass = (0.00319928, 0.120388, -0.0210924)
                        float3 physics:diagonalInertia = (0.0009724732, 0.0026420362, 0.0028723206)
                        float physics:mass = 0.947974
                        quatf physics:principalAxes = (-0.45136374, 0.5144442, 0.4627525, 0.56345195)

                        over "leg_right_knee_pitch" (
                            prepend apiSchemas = ["PhysicsRigidBodyAPI", "PhysicsMassAPI"]
                        )
                        {
                            point3f physics:centerOfMass = (-0.0000509429, 0.112249, -0.0257397)
                            float3 physics:diagonalInertia = (0.0005587799, 0.002038236, 0.002301266)
                            float physics:mass = 0.653864
                            quatf physics:principalAxes = (-0.5050904, 0.49445724, 0.5076365, 0.49264684)

                            over "leg_right_ankle_pitch" (
                                prepend apiSchemas = ["PhysicsRigidBodyAPI", "PhysicsMassAPI"]
                            )
                            {
                                point3f physics:centerOfMass = (0.0131065, 0.0273743, -0.0274153)
                                float3 physics:diagonalInertia = (0.00007969344, 0.0001337359, 0.00019949397)
                                float physics:mass = 0.106196
                                quatf physics:principalAxes = (0.6649288, 0.08027093, 0.7131654, 0.20693329)

                                over "leg_right_ankle_roll" (
                                    prepend apiSchemas = ["PhysicsRigidBodyAPI", "PhysicsMassAPI"]
                                )
                                {
                                    point3f physics:centerOfMass = (0.0000229341, 0.0226611, 0.0197836)
                                    float3 physics:diagonalInertia = (0.0006039032, 0.0019191763, 0.0019870535)
                                    float physics:mass = 0.706476
                                    quatf physics:principalAxes = (0.70614105, -0.041082144, 0.70593745, 0.036460835)

                                    over "box" (
                                        prepend apiSchemas = ["NewtonCollisionAPI"]
                                    )
                                    {
                                    }
                                }
                            }

                            over "cylinder" (
                                prepend apiSchemas = ["NewtonCollisionAPI"]
                            )
                            {
                            }
                        }

                        over "cylinder" (
                            prepend apiSchemas = ["NewtonCollisionAPI"]
                        )
                        {
                        }
                    }
                }
            }

            over "structure_left" (
                prepend apiSchemas = ["PhysicsRigidBodyAPI", "PhysicsMassAPI"]
            )
            {
                point3f physics:centerOfMass = (0, 0, 0)
                float3 physics:diagonalInertia = (0.002225, 0.00625, 0.007225)
                float physics:mass = 3
                quatf physics:principalAxes = (0.5, 0.5, 0.5, 0.5)

                over "box_1" (
                    prepend apiSchemas = ["NewtonCollisionAPI"]
                )
                {
                }
            }

            over "structure_right" (
                prepend apiSchemas = ["PhysicsRigidBodyAPI", "PhysicsMassAPI"]
            )
            {
                point3f physics:centerOfMass = (0, 0, 0)
                float3 physics:diagonalInertia = (0.002225, 0.00625, 0.007225)
                float physics:mass = 3
                quatf physics:principalAxes = (0.5, 0.5, 0.5, 0.5)

                over "box_1" (
                    prepend apiSchemas = ["NewtonCollisionAPI"]
                )
                {
                }
            }

            over "soarm_left_base_link" (
                prepend apiSchemas = ["PhysicsRigidBodyAPI", "PhysicsMassAPI"]
            )
            {
                point3f physics:centerOfMass = (0.0137179, -0.0000519711, 0.0334843)
                float3 physics:diagonalInertia = (0.00011323284, 0.00013180728, 0.00013612688)
                float physics:mass = 0.147
                quatf physics:principalAxes = (0.7018029, -0.69824415, -0.10709887, 0.0919654)

                over "soarm_left_shoulder_link" (
                    prepend apiSchemas = ["PhysicsRigidBodyAPI", "PhysicsMassAPI"]
                )
                {
                    point3f physics:centerOfMass = (-0.0307604, -0.0000166727, -0.0252713)
                    float3 physics:diagonalInertia = (0.00002395524, 0.00008103881, 0.000083783554)
                    float physics:mass = 0.100006
                    quatf physics:principalAxes = (0.7138759, -0.010394466, 0.70014614, -0.0082792565)

                    over "soarm_left_upper_arm_link" (
                        prepend apiSchemas = ["PhysicsRigidBodyAPI", "PhysicsMassAPI"]
                    )
                    {
                        point3f physics:centerOfMass = (-0.0898471, -0.00838224, 0.0184089)
                        float3 physics:diagonalInertia = (0.000037245056, 0.00014248698, 0.00015087317)
                        float physics:mass = 0.103
                        quatf physics:principalAxes = (-0.70363194, 0.7049951, 0.06271781, 0.06285316)

                        over "soarm_left_lower_arm_link" (
                            prepend apiSchemas = ["PhysicsRigidBodyAPI", "PhysicsMassAPI"]
                        )
                        {
                            point3f physics:centerOfMass = (-0.0980701, 0.00324376, 0.0182831)
                            float3 physics:diagonalInertia = (0.000028312457, 0.00014530364, 0.0001602617)
                            float physics:mass = 0.104
                            quatf physics:principalAxes = (-0.70618445, 0.70744777, -0.016095825, -0.0237087)

                            over "soarm_left_wrist_link" (
                                prepend apiSchemas = ["PhysicsRigidBodyAPI", "PhysicsMassAPI"]
                            )
                            {
                                point3f physics:centerOfMass = (-0.000103312, -0.0386143, 0.0281156)
                                float3 physics:diagonalInertia = (0.000018943443, 0.000027447377, 0.00003682648)
                                float physics:mass = 0.079
                                quatf physics:principalAxes = (0.68502074, -0.17966168, 0.68272656, 0.1798686)

                                over "soarm_left_gripper_link" (
                                    prepend apiSchemas = ["PhysicsRigidBodyAPI", "PhysicsMassAPI"]
                                )
                                {
                                    point3f physics:centerOfMass = (0.000213627, 0.000245138, -0.025187)
                                    float3 physics:diagonalInertia = (0.000024283921, 0.000037722886, 0.000043373493)
                                    float physics:mass = 0.087
                                    quatf physics:principalAxes = (-0.678361, 0.6897845, -0.17118166, 0.18633431)

                                    over "soarm_left_moving_jaw_link" (
                                        prepend apiSchemas = ["PhysicsRigidBodyAPI", "PhysicsMassAPI"]
                                    )
                                    {
                                        point3f physics:centerOfMass = (-0.00157495, -0.0300244, 0.0192755)
                                        float3 physics:diagonalInertia = (0.000001865226, 0.00000529092, 0.000006635824)
                                        float physics:mass = 0.012
                                        quatf physics:principalAxes = (-0.50899446, 0.52394825, 0.4742588, 0.49140763)
                                    }

                                    over "soarm_left_gripper_frame_link" (
                                        prepend apiSchemas = ["PhysicsRigidBodyAPI", "PhysicsMassAPI"]
                                    )
                                    {
                                        point3f physics:centerOfMass = (0, 0, 0)
                                        float3 physics:diagonalInertia = (0, 0, 0)
                                        float physics:mass = 1e-9
                                        quatf physics:principalAxes = (1, 0, 0, 0)
                                    }
                                }
                            }
                        }
                    }
                }
            }

            over "soarm_right_base_link" (
                prepend apiSchemas = ["PhysicsRigidBodyAPI", "PhysicsMassAPI"]
            )
            {
                point3f physics:centerOfMass = (0.0137179, -0.0000519711, 0.0334843)
                float3 physics:diagonalInertia = (0.00011323284, 0.00013180728, 0.00013612688)
                float physics:mass = 0.147
                quatf physics:principalAxes = (0.7018029, -0.69824415, -0.10709887, 0.0919654)

                over "soarm_right_shoulder_link" (
                    prepend apiSchemas = ["PhysicsRigidBodyAPI", "PhysicsMassAPI"]
                )
                {
                    point3f physics:centerOfMass = (-0.0307604, -0.0000166727, -0.0252713)
                    float3 physics:diagonalInertia = (0.00002395524, 0.00008103881, 0.000083783554)
                    float physics:mass = 0.100006
                    quatf physics:principalAxes = (0.7138759, -0.010394466, 0.70014614, -0.0082792565)

                    over "soarm_right_upper_arm_link" (
                        prepend apiSchemas = ["PhysicsRigidBodyAPI", "PhysicsMassAPI"]
                    )
                    {
                        point3f physics:centerOfMass = (-0.0898471, -0.00838224, 0.0184089)
                        float3 physics:diagonalInertia = (0.000037245056, 0.00014248698, 0.00015087317)
                        float physics:mass = 0.103
                        quatf physics:principalAxes = (-0.70363194, 0.7049951, 0.06271781, 0.06285316)

                        over "soarm_right_lower_arm_link" (
                            prepend apiSchemas = ["PhysicsRigidBodyAPI", "PhysicsMassAPI"]
                        )
                        {
                            point3f physics:centerOfMass = (-0.0980701, 0.00324376, 0.0182831)
                            float3 physics:diagonalInertia = (0.000028312457, 0.00014530364, 0.0001602617)
                            float physics:mass = 0.104
                            quatf physics:principalAxes = (-0.70618445, 0.70744777, -0.016095825, -0.0237087)

                            over "soarm_right_wrist_link" (
                                prepend apiSchemas = ["PhysicsRigidBodyAPI", "PhysicsMassAPI"]
                            )
                            {
                                point3f physics:centerOfMass = (-0.000103312, -0.0386143, 0.0281156)
                                float3 physics:diagonalInertia = (0.000018943443, 0.000027447377, 0.00003682648)
                                float physics:mass = 0.079
                                quatf physics:principalAxes = (0.68502074, -0.17966168, 0.68272656, 0.1798686)

                                over "soarm_right_gripper_link" (
                                    prepend apiSchemas = ["PhysicsRigidBodyAPI", "PhysicsMassAPI"]
                                )
                                {
                                    point3f physics:centerOfMass = (0.000213627, 0.000245138, -0.025187)
                                    float3 physics:diagonalInertia = (0.000024283921, 0.000037722886, 0.000043373493)
                                    float physics:mass = 0.087
                                    quatf physics:principalAxes = (-0.678361, 0.6897845, -0.17118166, 0.18633431)

                                    over "soarm_right_moving_jaw_link" (
                                        prepend apiSchemas = ["PhysicsRigidBodyAPI", "PhysicsMassAPI"]
                                    )
                                    {
                                        point3f physics:centerOfMass = (-0.00157495, -0.0300244, 0.0192755)
                                        float3 physics:diagonalInertia = (0.000001865226, 0.00000529092, 0.000006635824)
                                        float physics:mass = 0.012
                                        quatf physics:principalAxes = (-0.50899446, 0.52394825, 0.4742588, 0.49140763)
                                    }

                                    over "soarm_right_gripper_frame_link" (
                                        prepend apiSchemas = ["PhysicsRigidBodyAPI", "PhysicsMassAPI"]
                                    )
                                    {
                                        point3f physics:centerOfMass = (0, 0, 0)
                                        float3 physics:diagonalInertia = (0, 0, 0)
                                        float physics:mass = 1e-9
                                        quatf physics:principalAxes = (1, 0, 0, 0)
                                    }
                                }
                            }
                        }
                    }
                }
            }

            over "box" (
                prepend apiSchemas = ["NewtonCollisionAPI"]
            )
            {
            }
        }
    }

    over "Physics"
    {
        def PhysicsRevoluteJoint "leg_left_ankle_roll_joint" (
            prepend apiSchemas = ["PhysicsDriveAPI:angular", "PhysicsJointStateAPI:angular"]
        )
        {
            float drive:angular:physics:maxForce = 20
            uniform token physics:axis = "Z"
            custom rel physics:body0
            prepend rel physics:body0 = </hylion/Geometry/base/leg_left_hip_roll/leg_left_hip_yaw/leg_left_hip_pitch/leg_left_knee_pitch/leg_left_ankle_pitch>
            custom rel physics:body1
            prepend rel physics:body1 = </hylion/Geometry/base/leg_left_hip_roll/leg_left_hip_yaw/leg_left_hip_pitch/leg_left_knee_pitch/leg_left_ankle_pitch/leg_left_ankle_roll>
            point3f physics:localPos0 = (0.03, 0.05, 0.025)
            point3f physics:localPos1 = (0, 0, 0)
            quatf physics:localRot0 = (-0.70710546, 1.431041e-16, -0.7071081, 2.220446e-16)
            quatf physics:localRot1 = (1, 0, 0, 0)
            float physics:lowerLimit = -14.999978
            float physics:upperLimit = 14.999978
            custom float urdf:limit:effort = 20
            custom float urdf:limit:velocity = 15

            def Scope "joint_properties"
            {
                custom string urdf:friction = "0.1"
            }
        }

        def PhysicsRevoluteJoint "leg_left_ankle_pitch_joint" (
            prepend apiSchemas = ["PhysicsDriveAPI:angular", "PhysicsJointStateAPI:angular"]
        )
        {
            float drive:angular:physics:maxForce = 20
            uniform token physics:axis = "Z"
            custom rel physics:body0
            prepend rel physics:body0 = </hylion/Geometry/base/leg_left_hip_roll/leg_left_hip_yaw/leg_left_hip_pitch/leg_left_knee_pitch>
            custom rel physics:body1
            prepend rel physics:body1 = </hylion/Geometry/base/leg_left_hip_roll/leg_left_hip_yaw/leg_left_hip_pitch/leg_left_knee_pitch/leg_left_ankle_pitch>
            point3f physics:localPos0 = (-2.421674e-15, -0.16, -0.003)
            point3f physics:localPos1 = (0, 0, 0)
            quatf physics:localRot0 = (-0.0000013267949, 5.25764e-17, 2.7755576e-16, 1)
            quatf physics:localRot1 = (1, 0, 0, 0)
            float physics:lowerLimit = -44.999992
            float physics:upperLimit = 44.999992
            custom float urdf:limit:effort = 20
            custom float urdf:limit:velocity = 15

            def Scope "joint_properties"
            {
                custom string urdf:friction = "0.1"
            }
        }

        def PhysicsRevoluteJoint "leg_left_knee_pitch_joint" (
            prepend apiSchemas = ["PhysicsDriveAPI:angular", "PhysicsJointStateAPI:angular"]
        )
        {
            float drive:angular:physics:maxForce = 20
            uniform token physics:axis = "Z"
            custom rel physics:body0
            prepend rel physics:body0 = </hylion/Geometry/base/leg_left_hip_roll/leg_left_hip_yaw/leg_left_hip_pitch>
            custom rel physics:body1
            prepend rel physics:body1 = </hylion/Geometry/base/leg_left_hip_roll/leg_left_hip_yaw/leg_left_hip_pitch/leg_left_knee_pitch>
            point3f physics:localPos0 = (4.0939474e-16, 0.15, -0.018)
            point3f physics:localPos1 = (0, 0, 0)
            quatf physics:localRot0 = (0.0000013267949, -7.049933e-17, -4.9960036e-16, -1)
            quatf physics:localRot1 = (1, 0, 0, 0)
            float physics:lowerLimit = -1.5113997e-11
            float physics:upperLimit = 139.99994
            custom float urdf:limit:effort = 20
            custom float urdf:limit:velocity = 15

            def Scope "joint_properties"
            {
                custom string urdf:friction = "0.1"
            }
        }

        def PhysicsRevoluteJoint "leg_left_hip_pitch_joint" (
            prepend apiSchemas = ["PhysicsDriveAPI:angular", "PhysicsJointStateAPI:angular"]
        )
        {
            float drive:angular:physics:maxForce = 20
            uniform token physics:axis = "Z"
            custom rel physics:body0
            prepend rel physics:body0 = </hylion/Geometry/base/leg_left_hip_roll/leg_left_hip_yaw>
            custom rel physics:body1
            prepend rel physics:body1 = </hylion/Geometry/base/leg_left_hip_roll/leg_left_hip_yaw/leg_left_hip_pitch>
            point3f physics:localPos0 = (0.027, -5.551115e-17, 0.052)
            point3f physics:localPos1 = (0, 0, 0)
            quatf physics:localRot0 = (-0.65328044, -0.2705981, 0.65328246, 0.2705981)
            quatf physics:localRot1 = (1, 0, 0, 0)
            float physics:lowerLimit = -108.75025
            float physics:upperLimit = 56.250015
            custom float urdf:limit:effort = 20
            custom float urdf:limit:velocity = 15

            def Scope "joint_properties"
            {
                custom string urdf:friction = "0.1"
            }
        }

        def PhysicsRevoluteJoint "leg_left_hip_yaw_joint" (
            prepend apiSchemas = ["PhysicsDriveAPI:angular", "PhysicsJointStateAPI:angular"]
        )
        {
            float drive:angular:physics:maxForce = 20
            uniform token physics:axis = "Z"
            custom rel physics:body0
            prepend rel physics:body0 = </hylion/Geometry/base/leg_left_hip_roll>
            custom rel physics:body1
            prepend rel physics:body1 = </hylion/Geometry/base/leg_left_hip_roll/leg_left_hip_yaw>
            point3f physics:localPos0 = (0.027, 9.7144515e-17, -0.052)
            point3f physics:localPos1 = (0, 0, 0)
            quatf physics:localRot0 = (0.49999815, -0.5, 0.50000185, -0.5)
            quatf physics:localRot1 = (1, 0, 0, 0)
            float physics:lowerLimit = -56.250015
            float physics:upperLimit = 33.750023
            custom float urdf:limit:effort = 20
            custom float urdf:limit:velocity = 15

            def Scope "joint_properties"
            {
                custom string urdf:friction = "0.1"
            }
        }

        def PhysicsRevoluteJoint "leg_left_hip_roll_joint" (
            prepend apiSchemas = ["PhysicsDriveAPI:angular", "PhysicsJointStateAPI:angular"]
        )
        {
            float drive:angular:physics:maxForce = 20
            uniform token physics:axis = "Z"
            custom rel physics:body0
            prepend rel physics:body0 = </hylion/Geometry/base>
            custom rel physics:body1
            prepend rel physics:body1 = </hylion/Geometry/base/leg_left_hip_roll>
            point3f physics:localPos0 = (-0.0290919, 0.08, 0.542631)
            point3f physics:localPos1 = (0, 0, 0)
            quatf physics:localRot0 = (0.92387956, 2.1838716e-15, 0.38268337, -4.791179e-15)
            quatf physics:localRot1 = (1, 0, 0, 0)
            float physics:lowerLimit = -10.000004
            float physics:upperLimit = 90.00021
            custom float urdf:limit:effort = 20
            custom float urdf:limit:velocity = 15

            def Scope "joint_properties"
            {
                custom string urdf:friction = "0.1"
            }
        }

        def PhysicsRevoluteJoint "leg_right_ankle_roll_joint" (
            prepend apiSchemas = ["PhysicsDriveAPI:angular", "PhysicsJointStateAPI:angular"]
        )
        {
            float drive:angular:physics:maxForce = 20
            uniform token physics:axis = "Z"
            custom rel physics:body0
            prepend rel physics:body0 = </hylion/Geometry/base/leg_right_hip_roll/leg_right_hip_yaw/leg_right_hip_pitch/leg_right_knee_pitch/leg_right_ankle_pitch>
            custom rel physics:body1
            prepend rel physics:body1 = </hylion/Geometry/base/leg_right_hip_roll/leg_right_hip_yaw/leg_right_hip_pitch/leg_right_knee_pitch/leg_right_ankle_pitch/leg_right_ankle_roll>
            point3f physics:localPos0 = (0.03, 0.05, -0.025)
            point3f physics:localPos1 = (0, 0, 0)
            quatf physics:localRot0 = (0.70710546, 1.2911895e-16, 0.7071081, 2.7755576e-16)
            quatf physics:localRot1 = (1, 0, 0, 0)
            float physics:lowerLimit = -14.999978
            float physics:upperLimit = 14.999978
            custom float urdf:limit:effort = 20
            custom float urdf:limit:velocity = 15

            def Scope "joint_properties"
            {
                custom string urdf:friction = "0.1"
            }
        }

        def PhysicsRevoluteJoint "leg_right_ankle_pitch_joint" (
            prepend apiSchemas = ["PhysicsDriveAPI:angular", "PhysicsJointStateAPI:angular"]
        )
        {
            float drive:angular:physics:maxForce = 20
            uniform token physics:axis = "Z"
            custom rel physics:body0
            prepend rel physics:body0 = </hylion/Geometry/base/leg_right_hip_roll/leg_right_hip_yaw/leg_right_hip_pitch/leg_right_knee_pitch>
            custom rel physics:body1
            prepend rel physics:body1 = </hylion/Geometry/base/leg_right_hip_roll/leg_right_hip_yaw/leg_right_hip_pitch/leg_right_knee_pitch/leg_right_ankle_pitch>
            point3f physics:localPos0 = (1.3791052e-15, 0.16, 0.003)
            point3f physics:localPos1 = (0, 0, 0)
            quatf physics:localRot0 = (1, -3.893058e-18, 6.4058396e-23, -4.1498173e-23)
            quatf physics:localRot1 = (1, 0, 0, 0)
            float physics:lowerLimit = -44.999992
            float physics:upperLimit = 44.999992
            custom float urdf:limit:effort = 20
            custom float urdf:limit:velocity = 15

            def Scope "joint_properties"
            {
                custom string urdf:friction = "0.1"
            }
        }

        def PhysicsRevoluteJoint "leg_right_knee_pitch_joint" (
            prepend apiSchemas = ["PhysicsDriveAPI:angular", "PhysicsJointStateAPI:angular"]
        )
        {
            float drive:angular:physics:maxForce = 20
            uniform token physics:axis = "Z"
            custom rel physics:body0
            prepend rel physics:body0 = </hylion/Geometry/base/leg_right_hip_roll/leg_right_hip_yaw/leg_right_hip_pitch>
            custom rel physics:body1
            prepend rel physics:body1 = </hylion/Geometry/base/leg_right_hip_roll/leg_right_hip_yaw/leg_right_hip_pitch/leg_right_knee_pitch>
            point3f physics:localPos0 = (-2.6020852e-17, 0.15, 0.018)
            point3f physics:localPos1 = (0, 0, 0)
            quatf physics:localRot0 = (1, -3.893058e-18, 6.4058396e-23, -4.1498173e-23)
            quatf physics:localRot1 = (1, 0, 0, 0)
            float physics:lowerLimit = -6.4119708e-12
            float physics:upperLimit = 139.99994
            custom float urdf:limit:effort = 20
            custom float urdf:limit:velocity = 15

            def Scope "joint_properties"
            {
                custom string urdf:friction = "0.1"
            }
        }

        def PhysicsRevoluteJoint "leg_right_hip_pitch_joint" (
            prepend apiSchemas = ["PhysicsDriveAPI:angular", "PhysicsJointStateAPI:angular"]
        )
        {
            float drive:angular:physics:maxForce = 20
            uniform token physics:axis = "Z"
            custom rel physics:body0
            prepend rel physics:body0 = </hylion/Geometry/base/leg_right_hip_roll/leg_right_hip_yaw>
            custom rel physics:body1
            prepend rel physics:body1 = </hylion/Geometry/base/leg_right_hip_roll/leg_right_hip_yaw/leg_right_hip_pitch>
            point3f physics:localPos0 = (-0.027, -3.8857806e-16, 0.052)
            point3f physics:localPos1 = (0, 0, 0)
            quatf physics:localRot0 = (0.65328044, 0.2705981, -0.65328246, -0.2705981)
            quatf physics:localRot1 = (1, 0, 0, 0)
            float physics:lowerLimit = -108.75025
            float physics:upperLimit = 56.250015
            custom float urdf:limit:effort = 20
            custom float urdf:limit:velocity = 15

            def Scope "joint_properties"
            {
                custom string urdf:friction = "0.1"
            }
        }

        def PhysicsRevoluteJoint "leg_right_hip_yaw_joint" (
            prepend apiSchemas = ["PhysicsDriveAPI:angular", "PhysicsJointStateAPI:angular"]
        )
        {
            float drive:angular:physics:maxForce = 20
            uniform token physics:axis = "Z"
            custom rel physics:body0
            prepend rel physics:body0 = </hylion/Geometry/base/leg_right_hip_roll>
            custom rel physics:body1
            prepend rel physics:body1 = </hylion/Geometry/base/leg_right_hip_roll/leg_right_hip_yaw>
            point3f physics:localPos0 = (-0.027, 3.330669e-16, -0.052)
            point3f physics:localPos1 = (0, 0, 0)
            quatf physics:localRot0 = (-0.49999815, 0.5, 0.50000185, -0.5)
            quatf physics:localRot1 = (1, 0, 0, 0)
            float physics:lowerLimit = -33.750023
            float physics:upperLimit = 56.250015
            custom float urdf:limit:effort = 20
            custom float urdf:limit:velocity = 15

            def Scope "joint_properties"
            {
                custom string urdf:friction = "0.1"
            }
        }

        def PhysicsRevoluteJoint "leg_right_hip_roll_joint" (
            prepend apiSchemas = ["PhysicsDriveAPI:angular", "PhysicsJointStateAPI:angular"]
        )
        {
            float drive:angular:physics:maxForce = 20
            uniform token physics:axis = "Z"
            custom rel physics:body0
            prepend rel physics:body0 = </hylion/Geometry/base>
            custom rel physics:body1
            prepend rel physics:body1 = </hylion/Geometry/base/leg_right_hip_roll>
            point3f physics:localPos0 = (-0.0290919, -0.08, 0.542631)
            point3f physics:localPos1 = (0, 0, 0)
            quatf physics:localRot0 = (0.0000012257987, 0.38268337, -5.077423e-7, 0.92387956)
            quatf physics:localRot1 = (1, 0, 0, 0)
            float physics:lowerLimit = -90.00021
            float physics:upperLimit = 10.000004
            custom float urdf:limit:effort = 20
            custom float urdf:limit:velocity = 15

            def Scope "joint_properties"
            {
                custom string urdf:friction = "0.1"
            }
        }

        def PhysicsRevoluteJoint "soarm_left_shoulder_pan" (
            prepend apiSchemas = ["PhysicsDriveAPI:angular", "PhysicsJointStateAPI:angular"]
        )
        {
            float drive:angular:physics:maxForce = 10
            uniform token physics:axis = "Z"
            custom rel physics:body0
            prepend rel physics:body0 = </hylion/Geometry/base/soarm_left_base_link>
            custom rel physics:body1
            prepend rel physics:body1 = </hylion/Geometry/base/soarm_left_base_link/soarm_left_shoulder_link>
            point3f physics:localPos0 = (0.0388353, -8.97657e-9, 0.0624)
            point3f physics:localPos1 = (0, 0, 0)
            quatf physics:localRot0 = (-1.7606641e-12, -0.0000013267949, 1, 0.0000013267949)
            quatf physics:localRot1 = (1, 0, 0, 0)
            float physics:lowerLimit = -109.99988
            float physics:upperLimit = 109.99988
            custom float urdf:limit:effort = 10
            custom float urdf:limit:velocity = 10
        }

        def PhysicsRevoluteJoint "soarm_left_shoulder_lift" (
            prepend apiSchemas = ["PhysicsDriveAPI:angular", "PhysicsJointStateAPI:angular"]
        )
        {
            float drive:angular:physics:maxForce = 10
            uniform token physics:axis = "Z"
            custom rel physics:body0
            prepend rel physics:body0 = </hylion/Geometry/base/soarm_left_base_link/soarm_left_shoulder_link>
            custom rel physics:body1
            prepend rel physics:body1 = </hylion/Geometry/base/soarm_left_base_link/soarm_left_shoulder_link/soarm_left_upper_arm_link>
            point3f physics:localPos0 = (-0.0303992, -0.0182778, -0.0542)
            point3f physics:localPos1 = (0, 0, 0)
            quatf physics:localRot0 = (0.70710546, -0.7071081, 1.0357265e-16, -2.220446e-16)
            quatf physics:localRot1 = (1, 0, 0, 0)
            float physics:lowerLimit = -100.000046
            float physics:upperLimit = 100.000046
            custom float urdf:limit:effort = 10
            custom float urdf:limit:velocity = 10
        }

        def PhysicsRevoluteJoint "soarm_left_elbow_flex" (
            prepend apiSchemas = ["PhysicsDriveAPI:angular", "PhysicsJointStateAPI:angular"]
        )
        {
            float drive:angular:physics:maxForce = 10
            uniform token physics:axis = "Z"
            custom rel physics:body0
            prepend rel physics:body0 = </hylion/Geometry/base/soarm_left_base_link/soarm_left_shoulder_link/soarm_left_upper_arm_link>
            custom rel physics:body1
            prepend rel physics:body1 = </hylion/Geometry/base/soarm_left_base_link/soarm_left_shoulder_link/soarm_left_upper_arm_link/soarm_left_lower_arm_link>
            point3f physics:localPos0 = (-0.11257, -0.028, 1.700029e-16)
            point3f physics:localPos1 = (0, 0, 0)
            quatf physics:localRot0 = (1, -7.5269056e-23, 1.6903188e-17, 8.8961245e-23)
            quatf physics:localRot1 = (1, 0, 0, 0)
            float physics:lowerLimit = -95.99908
            float physics:upperLimit = 95.99908
            custom float urdf:limit:effort = 10
            custom float urdf:limit:velocity = 10
        }

        def PhysicsRevoluteJoint "soarm_left_wrist_flex" (
            prepend apiSchemas = ["PhysicsDriveAPI:angular", "PhysicsJointStateAPI:angular"]
        )
        {
            float drive:angular:physics:maxForce = 10
            uniform token physics:axis = "Z"
            custom rel physics:body0
            prepend rel physics:body0 = </hylion/Geometry/base/soarm_left_base_link/soarm_left_shoulder_link/soarm_left_upper_arm_link/soarm_left_lower_arm_link>
            custom rel physics:body1
            prepend rel physics:body1 = </hylion/Geometry/base/soarm_left_base_link/soarm_left_shoulder_link/soarm_left_upper_arm_link/soarm_left_lower_arm_link/soarm_left_wrist_link>
            point3f physics:localPos0 = (-0.1349, 0.0052, 3.8163916e-17)
            point3f physics:localPos1 = (0, 0, 0)
            quatf physics:localRot0 = (-0.70710546, -2.220446e-16, 4.4274836e-17, 0.7071081)
            quatf physics:localRot1 = (1, 0, 0, 0)
            float physics:lowerLimit = -94.99984
            float physics:upperLimit = 94.99984
            custom float urdf:limit:effort = 10
            custom float urdf:limit:velocity = 10
        }

        def PhysicsRevoluteJoint "soarm_left_wrist_roll" (
            prepend apiSchemas = ["PhysicsDriveAPI:angular", "PhysicsJointStateAPI:angular"]
        )
        {
            float drive:angular:physics:maxForce = 10
            uniform token physics:axis = "Z"
            custom rel physics:body0
            prepend rel physics:body0 = </hylion/Geometry/base/soarm_left_base_link/soarm_left_shoulder_link/soarm_left_upper_arm_link/soarm_left_lower_arm_link/soarm_left_wrist_link>
            custom rel physics:body1
            prepend rel physics:body1 = </hylion/Geometry/base/soarm_left_base_link/soarm_left_shoulder_link/soarm_left_upper_arm_link/soarm_left_lower_arm_link/soarm_left_wrist_link/soarm_left_gripper_link>
            point3f physics:localPos0 = (2.7755576e-17, -0.0611, 0.0181)
            point3f physics:localPos1 = (0, 0, 0)
            quatf physics:localRot0 = (-0.017210072, 0.017208133, -0.7068986, -0.706896)
            quatf physics:localRot1 = (1, 0, 0, 0)
            float physics:lowerLimit = -157.21103
            float physics:upperLimit = 162.78934
            custom float urdf:limit:effort = 10
            custom float urdf:limit:velocity = 10
        }

        def PhysicsRevoluteJoint "soarm_left_gripper" (
            prepend apiSchemas = ["PhysicsDriveAPI:angular", "PhysicsJointStateAPI:angular"]
        )
        {
            float drive:angular:physics:maxForce = 10
            uniform token physics:axis = "Z"
            custom rel physics:body0
            prepend rel physics:body0 = </hylion/Geometry/base/soarm_left_base_link/soarm_left_shoulder_link/soarm_left_upper_arm_link/soarm_left_lower_arm_link/soarm_left_wrist_link/soarm_left_gripper_link>
            custom rel physics:body1
            prepend rel physics:body1 = </hylion/Geometry/base/soarm_left_base_link/soarm_left_shoulder_link/soarm_left_upper_arm_link/soarm_left_lower_arm_link/soarm_left_wrist_link/soarm_left_gripper_link/soarm_left_moving_jaw_link>
            point3f physics:localPos0 = (0.0202, 0.0188, -0.0234)
            point3f physics:localPos1 = (0, 0, 0)
            quatf physics:localRot0 = (0.70710546, 0.7071081, -1.8536205e-8, 1.8536273e-8)
            quatf physics:localRot1 = (1, 0, 0, 0)
            float physics:lowerLimit = -10.000004
            float physics:upperLimit = 100.000046
            custom float urdf:limit:effort = 10
            custom float urdf:limit:velocity = 10
        }

        def PhysicsRevoluteJoint "soarm_right_shoulder_pan" (
            prepend apiSchemas = ["PhysicsDriveAPI:angular", "PhysicsJointStateAPI:angular"]
        )
        {
            float drive:angular:physics:maxForce = 10
            uniform token physics:axis = "Z"
            custom rel physics:body0
            prepend rel physics:body0 = </hylion/Geometry/base/soarm_right_base_link>
            custom rel physics:body1
            prepend rel physics:body1 = </hylion/Geometry/base/soarm_right_base_link/soarm_right_shoulder_link>
            point3f physics:localPos0 = (0.0388353, -8.97657e-9, 0.0624)
            point3f physics:localPos1 = (0, 0, 0)
            quatf physics:localRot0 = (-1.7605831e-12, -0.0000013267949, 1, 0.0000013267949)
            quatf physics:localRot1 = (1, 0, 0, 0)
            float physics:lowerLimit = -109.99988
            float physics:upperLimit = 109.99988
            custom float urdf:limit:effort = 10
            custom float urdf:limit:velocity = 10
        }

        def PhysicsRevoluteJoint "soarm_right_shoulder_lift" (
            prepend apiSchemas = ["PhysicsDriveAPI:angular", "PhysicsJointStateAPI:angular"]
        )
        {
            float drive:angular:physics:maxForce = 10
            uniform token physics:axis = "Z"
            custom rel physics:body0
            prepend rel physics:body0 = </hylion/Geometry/base/soarm_right_base_link/soarm_right_shoulder_link>
            custom rel physics:body1
            prepend rel physics:body1 = </hylion/Geometry/base/soarm_right_base_link/soarm_right_shoulder_link/soarm_right_upper_arm_link>
            point3f physics:localPos0 = (-0.0303992, -0.0182778, -0.0542)
            point3f physics:localPos1 = (0, 0, 0)
            quatf physics:localRot0 = (0.70710546, -0.7071081, 1.2406449e-16, -1.6653345e-16)
            quatf physics:localRot1 = (1, 0, 0, 0)
            float physics:lowerLimit = -100.000046
            float physics:upperLimit = 100.000046
            custom float urdf:limit:effort = 10
            custom float urdf:limit:velocity = 10
        }

        def PhysicsRevoluteJoint "soarm_right_elbow_flex" (
            prepend apiSchemas = ["PhysicsDriveAPI:angular", "PhysicsJointStateAPI:angular"]
        )
        {
            float drive:angular:physics:maxForce = 10
            uniform token physics:axis = "Z"
            custom rel physics:body0
            prepend rel physics:body0 = </hylion/Geometry/base/soarm_right_base_link/soarm_right_shoulder_link/soarm_right_upper_arm_link>
            custom rel physics:body1
            prepend rel physics:body1 = </hylion/Geometry/base/soarm_right_base_link/soarm_right_shoulder_link/soarm_right_upper_arm_link/soarm_right_lower_arm_link>
            point3f physics:localPos0 = (-0.11257, -0.028, 1.769418e-16)
            point3f physics:localPos1 = (0, 0, 0)
            quatf physics:localRot0 = (1, 1.4464397e-23, -3.4065128e-18, -2.479571e-22)
            quatf physics:localRot1 = (1, 0, 0, 0)
            float physics:lowerLimit = -95.99908
            float physics:upperLimit = 95.99908
            custom float urdf:limit:effort = 10
            custom float urdf:limit:velocity = 10
        }

        def PhysicsRevoluteJoint "soarm_right_wrist_flex" (
            prepend apiSchemas = ["PhysicsDriveAPI:angular", "PhysicsJointStateAPI:angular"]
        )
        {
            float drive:angular:physics:maxForce = 10
            uniform token physics:axis = "Z"
            custom rel physics:body0
            prepend rel physics:body0 = </hylion/Geometry/base/soarm_right_base_link/soarm_right_shoulder_link/soarm_right_upper_arm_link/soarm_right_lower_arm_link>
            custom rel physics:body1
            prepend rel physics:body1 = </hylion/Geometry/base/soarm_right_base_link/soarm_right_shoulder_link/soarm_right_upper_arm_link/soarm_right_lower_arm_link/soarm_right_wrist_link>
            point3f physics:localPos0 = (-0.1349, 0.0052, 3.8163916e-17)
            point3f physics:localPos1 = (0, 0, 0)
            quatf physics:localRot0 = (0.70710546, 1.110223e-16, -1.2591865e-16, -0.7071081)
            quatf physics:localRot1 = (1, 0, 0, 0)
            float physics:lowerLimit = -94.99984
            float physics:upperLimit = 94.99984
            custom float urdf:limit:effort = 10
            custom float urdf:limit:velocity = 10
        }

        def PhysicsRevoluteJoint "soarm_right_wrist_roll" (
            prepend apiSchemas = ["PhysicsDriveAPI:angular", "PhysicsJointStateAPI:angular"]
        )
        {
            float drive:angular:physics:maxForce = 10
            uniform token physics:axis = "Z"
            custom rel physics:body0
            prepend rel physics:body0 = </hylion/Geometry/base/soarm_right_base_link/soarm_right_shoulder_link/soarm_right_upper_arm_link/soarm_right_lower_arm_link/soarm_right_wrist_link>
            custom rel physics:body1
            prepend rel physics:body1 = </hylion/Geometry/base/soarm_right_base_link/soarm_right_shoulder_link/soarm_right_upper_arm_link/soarm_right_lower_arm_link/soarm_right_wrist_link/soarm_right_gripper_link>
            point3f physics:localPos0 = (2.7755576e-17, -0.0611, 0.0181)
            point3f physics:localPos1 = (0, 0, 0)
            quatf physics:localRot0 = (0.017210072, -0.017208133, 0.7068986, 0.706896)
            quatf physics:localRot1 = (1, 0, 0, 0)
            float physics:lowerLimit = -157.21103
            float physics:upperLimit = 162.78934
            custom float urdf:limit:effort = 10
            custom float urdf:limit:velocity = 10
        }

        def PhysicsRevoluteJoint "soarm_right_gripper" (
            prepend apiSchemas = ["PhysicsDriveAPI:angular", "PhysicsJointStateAPI:angular"]
        )
        {
            float drive:angular:physics:maxForce = 10
            uniform token physics:axis = "Z"
            custom rel physics:body0
            prepend rel physics:body0 = </hylion/Geometry/base/soarm_right_base_link/soarm_right_shoulder_link/soarm_right_upper_arm_link/soarm_right_lower_arm_link/soarm_right_wrist_link/soarm_right_gripper_link>
            custom rel physics:body1
            prepend rel physics:body1 = </hylion/Geometry/base/soarm_right_base_link/soarm_right_shoulder_link/soarm_right_upper_arm_link/soarm_right_lower_arm_link/soarm_right_wrist_link/soarm_right_gripper_link/soarm_right_moving_jaw_link>
            point3f physics:localPos0 = (0.0202, 0.0188, -0.0234)
            point3f physics:localPos1 = (0, 0, 0)
            quatf physics:localRot0 = (0.70710546, 0.7071081, -1.8536205e-8, 1.8536273e-8)
            quatf physics:localRot1 = (1, 0, 0, 0)
            float physics:lowerLimit = -10.000004
            float physics:upperLimit = 100.000046
            custom float urdf:limit:effort = 10
            custom float urdf:limit:velocity = 10
        }

        def PhysicsFixedJoint "root_joint"
        {
            custom rel physics:body0
            prepend rel physics:body0 = </hylion>
            custom rel physics:body1
            prepend rel physics:body1 = </hylion/Geometry/base>
            point3f physics:localPos0 = (0, 0, 0)
            point3f physics:localPos1 = (0, 0, 0)
            quatf physics:localRot0 = (1, 0, 0, 0)
            quatf physics:localRot1 = (1, 0, 0, 0)
        }

        def PhysicsFixedJoint "imu_frame"
        {
            custom rel physics:body0
            prepend rel physics:body0 = </hylion/Geometry/base/imu_2>
            custom rel physics:body1
            prepend rel physics:body1 = </hylion/Geometry/base/imu_2/imu>
            point3f physics:localPos0 = (0, -6.33816e-19, 0.005)
            point3f physics:localPos1 = (0, 0, 0)
            quatf physics:localRot0 = (1, 0, 0, 0)
            quatf physics:localRot1 = (1, 0, 0, 0)
        }

        def PhysicsFixedJoint "imu"
        {
            custom rel physics:body0
            prepend rel physics:body0 = </hylion/Geometry/base>
            custom rel physics:body1
            prepend rel physics:body1 = </hylion/Geometry/base/imu_2>
            point3f physics:localPos0 = (0.061722, -5.97549e-17, 0.68)
            point3f physics:localPos1 = (0, 0, 0)
            quatf physics:localRot0 = (1, 0, 0, 0)
            quatf physics:localRot1 = (1, 0, 0, 0)
            custom float urdf:limit:effort = 20
            custom float urdf:limit:velocity = 15

            def Scope "joint_properties"
            {
                custom string urdf:friction = "0.1"
            }
        }

        def PhysicsFixedJoint "structure_left_joint"
        {
            custom rel physics:body0
            prepend rel physics:body0 = </hylion/Geometry/base>
            custom rel physics:body1
            prepend rel physics:body1 = </hylion/Geometry/base/structure_left>
            point3f physics:localPos0 = (0, 0.095, 0.71)
            point3f physics:localPos1 = (0, 0, 0)
            quatf physics:localRot0 = (1, 0, 0, 0)
            quatf physics:localRot1 = (1, 0, 0, 0)
        }

        def PhysicsFixedJoint "structure_right_joint"
        {
            custom rel physics:body0
            prepend rel physics:body0 = </hylion/Geometry/base>
            custom rel physics:body1
            prepend rel physics:body1 = </hylion/Geometry/base/structure_right>
            point3f physics:localPos0 = (0, -0.095, 0.71)
            point3f physics:localPos1 = (0, 0, 0)
            quatf physics:localRot0 = (1, 0, 0, 0)
            quatf physics:localRot1 = (1, 0, 0, 0)
        }

        def PhysicsFixedJoint "soarm_left_base_joint"
        {
            custom rel physics:body0
            prepend rel physics:body0 = </hylion/Geometry/base>
            custom rel physics:body1
            prepend rel physics:body1 = </hylion/Geometry/base/soarm_left_base_link>
            point3f physics:localPos0 = (0, 0.12, 0.71)
            point3f physics:localPos1 = (0, 0, 0)
            quatf physics:localRot0 = (-0.49999815, 0.50000185, -0.5, -0.5)
            quatf physics:localRot1 = (1, 0, 0, 0)
        }

        def PhysicsFixedJoint "soarm_left_gripper_frame_joint"
        {
            custom rel physics:body0
            prepend rel physics:body0 = </hylion/Geometry/base/soarm_left_base_link/soarm_left_shoulder_link/soarm_left_upper_arm_link/soarm_left_lower_arm_link/soarm_left_wrist_link/soarm_left_gripper_link>
            custom rel physics:body1
            prepend rel physics:body1 = </hylion/Geometry/base/soarm_left_base_link/soarm_left_shoulder_link/soarm_left_upper_arm_link/soarm_left_lower_arm_link/soarm_left_wrist_link/soarm_left_gripper_link/soarm_left_gripper_frame_link>
            point3f physics:localPos0 = (-0.0079, -0.000218121, -0.0981274)
            point3f physics:localPos1 = (0, 0, 0)
            quatf physics:localRot0 = (0.0000013267949, 1.110223e-16, 1, -5.5373085e-17)
            quatf physics:localRot1 = (1, 0, 0, 0)
        }

        def PhysicsFixedJoint "soarm_right_base_joint"
        {
            custom rel physics:body0
            prepend rel physics:body0 = </hylion/Geometry/base>
            custom rel physics:body1
            prepend rel physics:body1 = </hylion/Geometry/base/soarm_right_base_link>
            point3f physics:localPos0 = (0, -0.12, 0.71)
            point3f physics:localPos1 = (0, 0, 0)
            quatf physics:localRot0 = (0.49999815, 0.50000185, 0.5, -0.5)
            quatf physics:localRot1 = (1, 0, 0, 0)
        }

        def PhysicsFixedJoint "soarm_right_gripper_frame_joint"
        {
            custom rel physics:body0
            prepend rel physics:body0 = </hylion/Geometry/base/soarm_right_base_link/soarm_right_shoulder_link/soarm_right_upper_arm_link/soarm_right_lower_arm_link/soarm_right_wrist_link/soarm_right_gripper_link>
            custom rel physics:body1
            prepend rel physics:body1 = </hylion/Geometry/base/soarm_right_base_link/soarm_right_shoulder_link/soarm_right_upper_arm_link/soarm_right_lower_arm_link/soarm_right_wrist_link/soarm_right_gripper_link/soarm_right_gripper_frame_link>
            point3f physics:localPos0 = (-0.0079, -0.000218121, -0.0981274)
            point3f physics:localPos1 = (0, 0, 0)
            quatf physics:localRot0 = (-0.0000013267949, -1.6653345e-16, -1, -7.6042806e-17)
            quatf physics:localRot1 = (1, 0, 0, 0)
        }
    }
}

